Workbook

Sheet Raw_Bookings
A1: RAW EXPORT - DO NOT EDIT (from CRM, monthly)
A2: BookingID | B2: Booking Date | C2: Customer | D2: Region | E2: Product | F2: Deal Type | G2: Sales Rep | H2: Amount (Local) | I2: Currency
A3: BK10311 | B3: 04/15/2024 | C3: Customer 113 | D3: central | E3: AnalyticsAddon | F3: Services | G3: Luis Ortega | H3: 139902.51 | I3: INR
A4: BK10041 | B4: 08/15/2024 | C4: Customer 045 | D4: west | E4: AnalyticsAddon | F4: Renewal | G4: Sara Cohen | H4: 7188.6 | I4: USD
A5: BK10034 | B5: 06/08/2024 | C5: Customer 078 | D5: Central | E5: SecuritySuite | F5: Renewal | G5: Luis Ortega | H5: 124686.99 | I5: CAD
A6: BK10161 | B6: 06/18/2024 | C6: Customer 053 | D6: SOUTH | E6: AnalyticsAddon | F6: Services | G6: Priya Sharma | H6: 111075.39 | I6: INR
A7: BK10277 | B7: 2025-01-08 | C7: Customer 076 | D7: East | E7: CorePlatform | F7: Services | G7: John Smith | H7: 169906.56 | I7: USD
A8: BK10318 | B8: 04/27/2025 | C8: Customer 076 | D8: East | E8: CorePlatform | F8: Support | G8: John Smith | H8: 41186.5 | I8: CAD
A9: BK10323 | B9: 06/16/2024 | C9: Customer 067 | D9: south | E9: SecuritySuite | F9: Renewal | G9: Anna Kowalski | H9: 68820.89 | I9: INR
A10: BK10260 | B10: 2024-02-02 | C10: Customer 049 | D10: EAST | E10: DataConnect | F10: New License | G10: Tom Becker | H10: 115704.41 | I10: GBP
A11: BK10074 | B11: 11/09/2024 | C11: Customer 071 | D11: Central | E11: SecuritySuite | F11: Services | G11: Luis Ortega | H11: 179403.77 | I11: EUR
A12: BK10018 | B12: 2024-09-10 | C12: Customer 044 | D12: West | E12: AnalyticsAddon | F12: Renewal | G12: Maria Garcia | H12: 4272.78 | I12: GBP
A13: BK10274 | B13: 45697 | C13: Customer 103 | D13: central | E13: DataConnect | F13: Support | G13: Luis Ortega | H13: 79219.07 | I13: INR
A14: BK10235 | B14: 45585 | C14: Customer 099 | D14: South | E14: DataConnect | F14: Support | G14: Priya Sharma | H14: 178735.62 | I14: USD
A15: BK10168 | B15: 45635 | C15: Customer 005 | D15: west | E15: DataConnect | F15: Renewal | G15: Maria Garcia | H15: 137314.88 | I15: EUR
A16: BK10197 | B16: 45453 | C16: Customer 062 | D16: SOUTH | E16: AnalyticsAddon | F16: Support | G16: Anna Kowalski | H16: 110378.87 | I16: USD
A17: BK10036 | B17: 45633 | C17: Customer 021 | D17: West | E17: DataConnect | F17: Services | G17: Sara Cohen | H17: 102280.52 | I17: USD
A18: BK10232 | B18: 45792 | C18: Customer 104 | D18: East | E18: DataConnect | F18: Renewal | G18: Tom Becker | H18: 93844.87 | I18: EUR
A19: BK10073 | B19: 45779 | C19: Customer 102 | D19: South | E19: CorePlatform | F19: Support | G19: Anna Kowalski | H19: 42222.56 | I19: GBP
A20: BK10256 | B20: 01/17/2025 | C20: Customer 085 | D20: EAST | E20: CorePlatform | F20: New License | G20: Tom Becker | H20: 97201.61 | I20: EUR
A21: BK10039 | B21: 2025-02-20 | C21: Customer 111 | D21: West | E21: AnalyticsAddon | F21: Services | G21: Maria Garcia | H21: 7387.19 | I21: INR
A22: BK10369 | B22: 01/31/2025 | C22: Customer 114 | D22: west | E22: SecuritySuite | F22: Renewal | G22: Sara Cohen | H22: 81902.22 | I22: USD
A23: BK10335 | B23: 45824 | C23: Customer 059 | D23: south | E23: CorePlatform | F23: New License | G23: Anna Kowalski | H23: 92460.71 | I23: GBP
A24: BK10090 | B24: 45399 | C24: Customer 053 | D24: West | E24: DataConnect | F24: Support | G24: Sara Cohen | H24: 120277.29 | I24: EUR
A25: BK10341 | B25: 11/02/2024 | C25: Customer 004 | D25: central | E25: DataConnect | F25: Renewal | G25: Wei Chen | H25: 19766.37 | I25: USD
A26: BK10371 | B26: 45379 | C26: Customer 097 | D26: Central | E26: AnalyticsAddon | F26: New License | G26: Luis Ortega | H26: 151821.1 | I26: INR
A27: BK10259 | B27: 01/17/2025 | C27: Customer 073 | D27: South | E27: AnalyticsAddon | F27: Support | G27: Anna Kowalski | H27: 124075.37 | I27: CAD
A28: BK10338 | B28: 45403 | C28: Customer 022 | D28: west | E28: DataConnect | F28: Support | G28: Maria Garcia | H28: 74952.72 | I28: EUR
A29: BK10399 | B29: 45374 | C29: Customer 081 | D29: South | E29: SecuritySuite | F29: New License | G29: Anna Kowalski | H29: 3834.29 | I29: USD
A30: BK10093 | B30: 03/28/2025 | C30: Customer 035 | D30: East | E30: SecuritySuite | F30: Services | G30: John Smith | H30: 158909.85 | I30: EUR
A31: BK10263 | B31: 01/17/2024 | C31: Customer 097 | D31: West | E31: DataConnect | F31: New License | G31: Maria Garcia | H31: 55972.01 | I31: EUR
A32: BK10356 | B32: 06/10/2024 | C32: Customer 084 | D32: SOUTH | E32: AnalyticsAddon | F32: Support | G32: Anna Kowalski | H32: 42512.99 | I32: EUR
A33: BK10072 | B33: 45574 | C33: Customer 011 | D33: East | E33: DataConnect | F33: Services | G33: John Smith | H33: 101266.19 | I33: USD
A34: BK10044 | B34: 12/19/2024 | C34: Customer 078 | D34: Central | E34: CorePlatform | F34: Services | G34: Luis Ortega | H34: 162212.34 | I34: USD
A35: BK10139 | B35: 45378 | C35: Customer 021 | D35: East | E35: CorePlatform | F35: Support | G35: John Smith | H35: 81431 | I35: EUR
A36: BK10064 | B36: 01/21/2024 | C36: Customer 017 | D36: west | E36: CorePlatform | F36: Renewal | G36: Maria Garcia | H36: 85311.02 | I36: USD
A37: BK10062 | B37: 04/10/2025 | C37: Customer 098 | D37: central | E37: SecuritySuite | F37: Services | G37: Luis Ortega | H37: 47652.06 | I37: USD
A38: BK10099 | B38: 01/21/2025 | C38: Customer 112 | D38: South | E38: AnalyticsAddon | F38: Services | G38: Anna Kowalski | H38: 44340.55 | I38: INR
A39: BK10174 | B39: 04/16/2024 | C39: Customer 006 | D39: central | E39: SecuritySuite | F39: Renewal | G39: Wei Chen | H39: 149977.91 | I39: GBP
A40: BK10155 | B40: 45359 | C40: Customer 072 | D40: Central | E40: DataConnect | F40: Support | G40: Wei Chen | H40: 47603.25 | I40: CAD
...

Sheet Rates
A1: Currency | B1: Rate to USD | C1: Effective Date | D1: Source
A2: USD | B2: 1 | C2: 45292 | D2: Finance rate card | F2: Priya updates rates on the 1st. DO NOT TOUCH!!
A3: EUR | B3: 1.09 | C3: 45292 | D3: Finance rate card
A4: GBP | B4: 1.28 | C4: 45292 | D4: Finance rate card | F4: TODO: add BRL when Brazil deals close (ask Finance)
A5: INR | B5: 0.012 | C5: 45292 | D5: Finance rate card
A6: CAD | B6: 0.74 | C6: 45292 | D6: Finance rate card

Sheet Rep_Targets
A1: Rep ID | B1: Sales Rep | C1: Target Year | D1: Annual Quota (USD)
A2: REP001 | B2: Jon Smith | C2: 2024 | D2: 1400000
A3: REP002 | B3: Maria Garcia | C3: 2024 | D3: 1250000
A4: REP003 | B4: Wei Chen | C4: 2024 | D4: 900000
A5: REP004 | B5: Priya Sharma | C5: 2024 | D5: 1400000
A6: REP005 | B6: Tom Becker | C6: 2024 | D6: 1100000
A7: REP006 | B7: Sara Cohen | C7: 2024 | D7: 1250000
A8: REP007 | B8: Luis Ortega | C8: 2024 | D8: 1400000
A9: REP008 | B9: Ana Kowalski | C9: 2024 | D9: 1100000

Sheet Rep_Master
A1: Alias Name | B1: Canonical Name | C1: Rep ID | D1: Region
A2: John Smith | B2: John Smith | C2: REP001 | D2: East
A3: Jon Smith | B3: John Smith | C3: REP001 | D3: East
A4: Maria Garcia | B4: Maria Garcia | C4: REP002 | D4: West
A5: Wei Chen | B5: Wei Chen | C5: REP003 | D5: Central
A6: Priya Sharma | B6: Priya Sharma | C6: REP004 | D6: South
A7: Tom Becker | B7: Tom Becker | C7: REP005 | D7: East
A8: Sara Cohen | B8: Sara Cohen | C8: REP006 | D8: West
A9: Luis Ortega | B9: Luis Ortega | C9: REP007 | D9: Central
A10: Anna Kowalski | B10: Anna Kowalski | C10: REP008 | D10: South
A11: Ana Kowalski | B11: Anna Kowalski | C11: REP008 | D11: South

Sheet Calc
A1: BookingID | B1: Clean Region | C1: Amount USD | D1: Deal Category | E1: Rep ID | F1: Rep Quota | G1: Attainment Status | H1: Adjusted USD | I1: Adjustment ID | J1: Adjustment Source
A2: =Raw_Bookings!A3 | B2: =IF(TRIM(LOWER(Raw_Bookings!D3))="east","East",IF(TRIM(LOWER(Raw_Bookings!D3))="west","West",IF(TRIM(LOWER(Raw_Bookings!D3))="central","Central",IF(TRIM(LOWER(Raw_Bookings!D3))="south","South","UNKNOWN")))) | C2: =IFERROR(Raw_Bookings!H3*VLOOKUP(Raw_Bookings!I3,Rates!$A$2:$B$6,2,FALSE),Raw_Bookings!H3) | D2: =IF(Raw_Bookings!F3="New License","NEW",IF(OR(Raw_Bookings!F3="Renewal",Raw_Bookings!F3="Support"),"RECURRING","OTHER")) | E2: =IFERROR(VLOOKUP(Raw_Bookings!G3,Rep_Master!$A$2:$D$18,3,FALSE),"") | F2: =IFERROR(VLOOKUP(E2,Rep_Targets!$A$2:$D$9,4,FALSE),0) | G2: =IF(F2=0,"NO QUOTA FOUND",IF(C2>=F2*0.25,"On Track","Behind")) | H2: =C2*IF(B2="West",0.95,1)
A3: =Raw_Bookings!A4 | B3: =IF(TRIM(LOWER(Raw_Bookings!D4))="east","East",IF(TRIM(LOWER(Raw_Bookings!D4))="west","West",IF(TRIM(LOWER(Raw_Bookings!D4))="central","Central",IF(TRIM(LOWER(Raw_Bookings!D4))="south","South","UNKNOWN")))) | C3: =IFERROR(Raw_Bookings!H4*VLOOKUP(Raw_Bookings!I4,Rates!$A$2:$B$6,2,FALSE),Raw_Bookings!H4) | D3: =IF(Raw_Bookings!F4="New License","NEW",IF(OR(Raw_Bookings!F4="Renewal",Raw_Bookings!F4="Support"),"RECURRING","OTHER")) | E3: =IFERROR(VLOOKUP(Raw_Bookings!G4,Rep_Master!$A$2:$D$18,3,FALSE),"") | F3: =IFERROR(VLOOKUP(E3,Rep_Targets!$A$2:$D$9,4,FALSE),0) | G3: =IF(F3=0,"NO QUOTA FOUND",IF(C3>=F3*0.25,"On Track","Behind")) | H3: =C3*IF(B3="West",0.95,1)
A4: =Raw_Bookings!A5 | B4: =IF(TRIM(LOWER(Raw_Bookings!D5))="east","East",IF(TRIM(LOWER(Raw_Bookings!D5))="west","West",IF(TRIM(LOWER(Raw_Bookings!D5))="central","Central",IF(TRIM(LOWER(Raw_Bookings!D5))="south","South","UNKNOWN")))) | C4: =IFERROR(Raw_Bookings!H5*VLOOKUP(Raw_Bookings!I5,Rates!$A$2:$B$6,2,FALSE),Raw_Bookings!H5) | D4: =IF(Raw_Bookings!F5="New License","NEW",IF(OR(Raw_Bookings!F5="Renewal",Raw_Bookings!F5="Support"),"RECURRING","OTHER")) | E4: =IFERROR(VLOOKUP(Raw_Bookings!G5,Rep_Master!$A$2:$D$18,3,FALSE),"") | F4: =IFERROR(VLOOKUP(E4,Rep_Targets!$A$2:$D$9,4,FALSE),0) | G4: =IF(F4=0,"NO QUOTA FOUND",IF(C4>=F4*0.25,"On Track","Behind")) | H4: =C4*IF(B4="West",0.95,1)
A5: =Raw_Bookings!A6 | B5: =IF(TRIM(LOWER(Raw_Bookings!D6))="east","East",IF(TRIM(LOWER(Raw_Bookings!D6))="west","West",IF(TRIM(LOWER(Raw_Bookings!D6))="central","Central",IF(TRIM(LOWER(Raw_Bookings!D6))="south","South","UNKNOWN")))) | C5: =IFERROR(Raw_Bookings!H6*VLOOKUP(Raw_Bookings!I6,Rates!$A$2:$B$6,2,FALSE),Raw_Bookings!H6) | D5: =IF(Raw_Bookings!F6="New License","NEW",IF(OR(Raw_Bookings!F6="Renewal",Raw_Bookings!F6="Support"),"RECURRING","OTHER")) | E5: =IFERROR(VLOOKUP(Raw_Bookings!G6,Rep_Master!$A$2:$D$18,3,FALSE),"") | F5: =IFERROR(VLOOKUP(E5,Rep_Targets!$A$2:$D$9,4,FALSE),0) | G5: =IF(F5=0,"NO QUOTA FOUND",IF(C5>=F5*0.25,"On Track","Behind")) | H5: =C5*IF(B5="West",0.95,1)
A6: =Raw_Bookings!A7 | B6: =IF(TRIM(LOWER(Raw_Bookings!D7))="east","East",IF(TRIM(LOWER(Raw_Bookings!D7))="west","West",IF(TRIM(LOWER(Raw_Bookings!D7))="central","Central",IF(TRIM(LOWER(Raw_Bookings!D7))="south","South","UNKNOWN")))) | C6: =IFERROR(Raw_Bookings!H7*VLOOKUP(Raw_Bookings!I7,Rates!$A$2:$B$6,2,FALSE),Raw_Bookings!H7) | D6: =IF(Raw_Bookings!F7="New License","NEW",IF(OR(Raw_Bookings!F7="Renewal",Raw_Bookings!F7="Support"),"RECURRING","OTHER")) | E6: =IFERROR(VLOOKUP(Raw_Bookings!G7,Rep_Master!$A$2:$D$18,3,FALSE),"") | F6: =IFERROR(VLOOKUP(E6,Rep_Targets!$A$2:$D$9,4,FALSE),0) | G6: =IF(F6=0,"NO QUOTA FOUND",IF(C6>=F6*0.25,"On Track","Behind")) | H6: =C6*IF(B6="West",0.95,1)
A7: =Raw_Bookings!A8 | B7: =IF(TRIM(LOWER(Raw_Bookings!D8))="east","East",IF(TRIM(LOWER(Raw_Bookings!D8))="west","West",IF(TRIM(LOWER(Raw_Bookings!D8))="central","Central",IF(TRIM(LOWER(Raw_Bookings!D8))="south","South","UNKNOWN")))) | C7: =IFERROR(Raw_Bookings!H8*VLOOKUP(Raw_Bookings!I8,Rates!$A$2:$B$6,2,FALSE),Raw_Bookings!H8) | D7: =IF(Raw_Bookings!F8="New License","NEW",IF(OR(Raw_Bookings!F8="Renewal",Raw_Bookings!F8="Support"),"RECURRING","OTHER")) | E7: =IFERROR(VLOOKUP(Raw_Bookings!G8,Rep_Master!$A$2:$D$18,3,FALSE),"") | F7: =IFERROR(VLOOKUP(E7,Rep_Targets!$A$2:$D$9,4,FALSE),0) | G7: =IF(F7=0,"NO QUOTA FOUND",IF(C7>=F7*0.25,"On Track","Behind")) | H7: =C7*IF(B7="West",0.95,1)
A8: =Raw_Bookings!A9 | B8: =IF(TRIM(LOWER(Raw_Bookings!D9))="east","East",IF(TRIM(LOWER(Raw_Bookings!D9))="west","West",IF(TRIM(LOWER(Raw_Bookings!D9))="central","Central",IF(TRIM(LOWER(Raw_Bookings!D9))="south","South","UNKNOWN")))) | C8: =IFERROR(Raw_Bookings!H9*VLOOKUP(Raw_Bookings!I9,Rates!$A$2:$B$6,2,FALSE),Raw_Bookings!H9) | D8: =IF(Raw_Bookings!F9="New License","NEW",IF(OR(Raw_Bookings!F9="Renewal",Raw_Bookings!F9="Support"),"RECURRING","OTHER")) | E8: =IFERROR(VLOOKUP(Raw_Bookings!G9,Rep_Master!$A$2:$D$18,3,FALSE),"") | F8: =IFERROR(VLOOKUP(E8,Rep_Targets!$A$2:$D$9,4,FALSE),0) | G8: =IF(F8=0,"NO QUOTA FOUND",IF(C8>=F8*0.25,"On Track","Behind")) | H8: =C8*IF(B8="West",0.95,1)
A9: =Raw_Bookings!A10 | B9: =IF(TRIM(LOWER(Raw_Bookings!D10))="east","East",IF(TRIM(LOWER(Raw_Bookings!D10))="west","West",IF(TRIM(LOWER(Raw_Bookings!D10))="central","Central",IF(TRIM(LOWER(Raw_Bookings!D10))="south","South","UNKNOWN")))) | C9: =IFERROR(Raw_Bookings!H10*VLOOKUP(Raw_Bookings!I10,Rates!$A$2:$B$6,2,FALSE),Raw_Bookings!H10) | D9: =IF(Raw_Bookings!F10="New License","NEW",IF(OR(Raw_Bookings!F10="Renewal",Raw_Bookings!F10="Support"),"RECURRING","OTHER")) | E9: =IFERROR(VLOOKUP(Raw_Bookings!G10,Rep_Master!$A$2:$D$18,3,FALSE),"") | F9: =IFERROR(VLOOKUP(E9,Rep_Targets!$A$2:$D$9,4,FALSE),0) | G9: =IF(F9=0,"NO QUOTA FOUND",IF(C9>=F9*0.25,"On Track","Behind")) | H9: =C9*IF(B9="West",0.95,1)
A10: =Raw_Bookings!A11 | B10: =IF(TRIM(LOWER(Raw_Bookings!D11))="east","East",IF(TRIM(LOWER(Raw_Bookings!D11))="west","West",IF(TRIM(LOWER(Raw_Bookings!D11))="central","Central",IF(TRIM(LOWER(Raw_Bookings!D11))="south","South","UNKNOWN")))) | C10: =IFERROR(Raw_Bookings!H11*VLOOKUP(Raw_Bookings!I11,Rates!$A$2:$B$6,2,FALSE),Raw_Bookings!H11) | D10: =IF(Raw_Bookings!F11="New License","NEW",IF(OR(Raw_Bookings!F11="Renewal",Raw_Bookings!F11="Support"),"RECURRING","OTHER")) | E10: =IFERROR(VLOOKUP(Raw_Bookings!G11,Rep_Master!$A$2:$D$18,3,FALSE),"") | F10: =IFERROR(VLOOKUP(E10,Rep_Targets!$A$2:$D$9,4,FALSE),0) | G10: =IF(F10=0,"NO QUOTA FOUND",IF(C10>=F10*0.25,"On Track","Behind")) | H10: =C10*IF(B10="West",0.95,1)
A11: =Raw_Bookings!A12 | B11: =IF(TRIM(LOWER(Raw_Bookings!D12))="east","East",IF(TRIM(LOWER(Raw_Bookings!D12))="west","West",IF(TRIM(LOWER(Raw_Bookings!D12))="central","Central",IF(TRIM(LOWER(Raw_Bookings!D12))="south","South","UNKNOWN")))) | C11: =IFERROR(Raw_Bookings!H12*VLOOKUP(Raw_Bookings!I12,Rates!$A$2:$B$6,2,FALSE),Raw_Bookings!H12) | D11: =IF(Raw_Bookings!F12="New License","NEW",IF(OR(Raw_Bookings!F12="Renewal",Raw_Bookings!F12="Support"),"RECURRING","OTHER")) | E11: =IFERROR(VLOOKUP(Raw_Bookings!G12,Rep_Master!$A$2:$D$18,3,FALSE),"") | F11: =IFERROR(VLOOKUP(E11,Rep_Targets!$A$2:$D$9,4,FALSE),0) | G11: =IF(F11=0,"NO QUOTA FOUND",IF(C11>=F11*0.25,"On Track","Behind")) | H11: =C11*IF(B11="West",0.95,1)
A12: =Raw_Bookings!A13 | B12: =IF(TRIM(LOWER(Raw_Bookings!D13))="east","East",IF(TRIM(LOWER(Raw_Bookings!D13))="west","West",IF(TRIM(LOWER(Raw_Bookings!D13))="central","Central",IF(TRIM(LOWER(Raw_Bookings!D13))="south","South","UNKNOWN")))) | C12: =IFERROR(Raw_Bookings!H13*VLOOKUP(Raw_Bookings!I13,Rates!$A$2:$B$6,2,FALSE),Raw_Bookings!H13) | D12: =IF(Raw_Bookings!F13="New License","NEW",IF(OR(Raw_Bookings!F13="Renewal",Raw_Bookings!F13="Support"),"RECURRING","OTHER")) | E12: =IFERROR(VLOOKUP(Raw_Bookings!G13,Rep_Master!$A$2:$D$18,3,FALSE),"") | F12: =IFERROR(VLOOKUP(E12,Rep_Targets!$A$2:$D$9,4,FALSE),0) | G12: =IF(F12=0,"NO QUOTA FOUND",IF(C12>=F12*0.25,"On Track","Behind")) | H12: =C12*IF(B12="West",0.95,1)
A13: =Raw_Bookings!A14 | B13: =IF(TRIM(LOWER(Raw_Bookings!D14))="east","East",IF(TRIM(LOWER(Raw_Bookings!D14))="west","West",IF(TRIM(LOWER(Raw_Bookings!D14))="central","Central",IF(TRIM(LOWER(Raw_Bookings!D14))="south","South","UNKNOWN")))) | C13: =IFERROR(Raw_Bookings!H14*VLOOKUP(Raw_Bookings!I14,Rates!$A$2:$B$6,2,FALSE),Raw_Bookings!H14) | D13: =IF(Raw_Bookings!F14="New License","NEW",IF(OR(Raw_Bookings!F14="Renewal",Raw_Bookings!F14="Support"),"RECURRING","OTHER")) | E13: =IFERROR(VLOOKUP(Raw_Bookings!G14,Rep_Master!$A$2:$D$18,3,FALSE),"") | F13: =IFERROR(VLOOKUP(E13,Rep_Targets!$A$2:$D$9,4,FALSE),0) | G13: =IF(F13=0,"NO QUOTA FOUND",IF(C13>=F13*0.25,"On Track","Behind")) | H13: =C13*IF(B13="West",0.95,1)
... A43: =Raw_Bookings!A44 | B43: =IF(TRIM(LOWER(Raw_Bookings!D44))="east","East",IF(TRIM(LOWER(Raw_Bookings!D44))="west","West",IF(TRIM(LOWER(Raw_Bookings!D44))="central","Central",IF(TRIM(LOWER(Raw_Bookings!D44))="south","South","UNKNOWN")))) | C43: =IFERROR(Raw_Bookings!H44*VLOOKUP(Raw_Bookings!I44,Rates!$A$2:$B$6,2,FALSE),Raw_Bookings!H44) | D43: =IF(Raw_Bookings!F44="New License","NEW",IF(OR(Raw_Bookings!F44="Renewal",Raw_Bookings!F44="Support"),"RECURRING","OTHER")) | E43: =IFERROR(VLOOKUP(Raw_Bookings!G44,Rep_Master!$A$2:$D$18,3,FALSE),"") | F43: =IFERROR(VLOOKUP(E43,Rep_Targets!$A$2:$D$9,4,FALSE),0) | G43: =IF(F43=0,"NO QUOTA FOUND",IF(C43>=F43*0.25,"On Track","Behind")) | H43: =C43*IF(B43="West",0.95,1)
A44: =Raw_Bookings!A45 | B44: =IF(TRIM(LOWER(Raw_Bookings!D45))="east","East",IF(TRIM(LOWER(Raw_Bookings!D45))="west","West",IF(TRIM(LOWER(Raw_Bookings!D45))="central","Central",IF(TRIM(LOWER(Raw_Bookings!D45))="south","South","UNKNOWN")))) | C44: =IFERROR(Raw_Bookings!H45*VLOOKUP(Raw_Bookings!I45,Rates!$A$2:$B$6,2,FALSE),Raw_Bookings!H45) | D44: =IF(Raw_Bookings!F45="New License","NEW",IF(OR(Raw_Bookings!F45="Renewal",Raw_Bookings!F45="Support"),"RECURRING","OTHER")) | E44: =IFERROR(VLOOKUP(Raw_Bookings!G45,Rep_Master!$A$2:$D$18,3,FALSE),"") | F44: =IFERROR(VLOOKUP(E44,Rep_Targets!$A$2:$D$9,4,FALSE),0) | G44: =IF(F44=0,"NO QUOTA FOUND",IF(C44>=F44*0.25,"On Track","Behind")) | H44: 26913.42 | I44: ADJ043 | J44: mgr adj - see email 3/12
A45: =Raw_Bookings!A46 | B45: =IF(TRIM(LOWER(Raw_Bookings!D46))="east","East",IF(TRIM(LOWER(Raw_Bookings!D46))="west","West",IF(TRIM(LOWER(Raw_Bookings!D46))="central","Central",IF(TRIM(LOWER(Raw_Bookings!D46))="south","South","UNKNOWN")))) | C45: =IFERROR(Raw_Bookings!H46*VLOOKUP(Raw_Bookings!I46,Rates!$A$2:$B$6,2,FALSE),Raw_Bookings!H46) | D45: =IF(Raw_Bookings!F46="New License","NEW",IF(OR(Raw_Bookings!F46="Renewal",Raw_Bookings!F46="Support"),"RECURRING","OTHER")) | E45: =IFERROR(VLOOKUP(Raw_Bookings!G46,Rep_Master!$A$2:$D$18,3,FALSE),"") | F45: =IFERROR(VLOOKUP(E45,Rep_Targets!$A$2:$D$9,4,FALSE),0) | G45: =IF(F45=0,"NO QUOTA FOUND",IF(C45>=F45*0.25,"On Track","Behind")) | H45: =C45*IF(B45="West",0.95,1)
A46: =Raw_Bookings!A47 | B46: =IF(TRIM(LOWER(Raw_Bookings!D47))="east","East",IF(TRIM(LOWER(Raw_Bookings!D47))="west","West",IF(TRIM(LOWER(Raw_Bookings!D47))="central","Central",IF(TRIM(LOWER(Raw_Bookings!D47))="south","South","UNKNOWN")))) | C46: =IFERROR(Raw_Bookings!H47*VLOOKUP(Raw_Bookings!I47,Rates!$A$2:$B$6,2,FALSE),Raw_Bookings!H47) | D46: =IF(Raw_Bookings!F47="New License","NEW",IF(OR(Raw_Bookings!F47="Renewal",Raw_Bookings!F47="Support"),"RECURRING","OTHER")) | E46: =IFERROR(VLOOKUP(Raw_Bookings!G47,Rep_Master!$A$2:$D$18,3,FALSE),"") | F46: =IFERROR(VLOOKUP(E46,Rep_Targets!$A$2:$D$9,4,FALSE),0) | G46: =IF(F46=0,"NO QUOTA FOUND",IF(C46>=F46*0.25,"On Track","Behind")) | H46: =C46*IF(B46="West",0.95,1)
A47: =Raw_Bookings!A48 | B47: =IF(TRIM(LOWER(Raw_Bookings!D48))="east","East",IF(TRIM(LOWER(Raw_Bookings!D48))="west","West",IF(TRIM(LOWER(Raw_Bookings!D48))="central","Central",IF(TRIM(LOWER(Raw_Bookings!D48))="south","South","UNKNOWN")))) | C47: =IFERROR(Raw_Bookings!H48*VLOOKUP(Raw_Bookings!I48,Rates!$A$2:$B$6,2,FALSE),Raw_Bookings!H48) | D47: =IF(Raw_Bookings!F48="New License","NEW",IF(OR(Raw_Bookings!F48="Renewal",Raw_Bookings!F48="Support"),"RECURRING","OTHER")) | E47: =IFERROR(VLOOKUP(Raw_Bookings!G48,Rep_Master!$A$2:$D$18,3,FALSE),"") | F47: =IFERROR(VLOOKUP(E47,Rep_Targets!$A$2:$D$9,4,FALSE),0) | G47: =IF(F47=0,"NO QUOTA FOUND",IF(C47>=F47*0.25,"On Track","Behind")) | H47: =C47*IF(B47="West",0.95,1)
A48: =Raw_Bookings!A49 | B48: =IF(TRIM(LOWER(Raw_Bookings!D49))="east","East",IF(TRIM(LOWER(Raw_Bookings!D49))="west","West",IF(TRIM(LOWER(Raw_Bookings!D49))="central","Central",IF(TRIM(LOWER(Raw_Bookings!D49))="south","South","UNKNOWN")))) | C48: =IFERROR(Raw_Bookings!H49*VLOOKUP(Raw_Bookings!I49,Rates!$A$2:$B$6,2,FALSE),Raw_Bookings!H49) | D48: =IF(Raw_Bookings!F49="New License","NEW",IF(OR(Raw_Bookings!F49="Renewal",Raw_Bookings!F49="Support"),"RECURRING","OTHER")) | E48: =IFERROR(VLOOKUP(Raw_Bookings!G49,Rep_Master!$A$2:$D$18,3,FALSE),"") | F48: =IFERROR(VLOOKUP(E48,Rep_Targets!$A$2:$D$9,4,FALSE),0) | G48: =IF(F48=0,"NO QUOTA FOUND",IF(C48>=F48*0.25,"On Track","Behind")) | H48: =C48*IF(B48="West",0.95,1)
A49: =Raw_Bookings!A50 | B49: =IF(TRIM(LOWER(Raw_Bookings!D50))="east","East",IF(TRIM(LOWER(Raw_Bookings!D50))="west","West",IF(TRIM(LOWER(Raw_Bookings!D50))="central","Central",IF(TRIM(LOWER(Raw_Bookings!D50))="south","South","UNKNOWN")))) | C49: =IFERROR(Raw_Bookings!H50*VLOOKUP(Raw_Bookings!I50,Rates!$A$2:$B$6,2,FALSE),Raw_Bookings!H50) | D49: =IF(Raw_Bookings!F50="New License","NEW",IF(OR(Raw_Bookings!F50="Renewal",Raw_Bookings!F50="Support"),"RECURRING","OTHER")) | E49: =IFERROR(VLOOKUP(Raw_Bookings!G50,Rep_Master!$A$2:$D$18,3,FALSE),"") | F49: =IFERROR(VLOOKUP(E49,Rep_Targets!$A$2:$D$9,4,FALSE),0) | G49: =IF(F49=0,"NO QUOTA FOUND",IF(C49>=F49*0.25,"On Track","Behind")) | H49: =C49*IF(B49="West",0.95,1)
A50: =Raw_Bookings!A51 | B50: =IF(TRIM(LOWER(Raw_Bookings!D51))="east","East",IF(TRIM(LOWER(Raw_Bookings!D51))="west","West",IF(TRIM(LOWER(Raw_Bookings!D51))="central","Central",IF(TRIM(LOWER(Raw_Bookings!D51))="south","South","UNKNOWN")))) | C50: =IFERROR(Raw_Bookings!H51*VLOOKUP(Raw_Bookings!I51,Rates!$A$2:$B$6,2,FALSE),Raw_Bookings!H51) | D50: =IF(Raw_Bookings!F51="New License","NEW",IF(OR(Raw_Bookings!F51="Renewal",Raw_Bookings!F51="Support"),"RECURRING","OTHER")) | E50: =IFERROR(VLOOKUP(Raw_Bookings!G51,Rep_Master!$A$2:$D$18,3,FALSE),"") | F50: =IFERROR(VLOOKUP(E50,Rep_Targets!$A$2:$D$9,4,FALSE),0) | G50: =IF(F50=0,"NO QUOTA FOUND",IF(C50>=F50*0.25,"On Track","Behind")) | H50: =C50*IF(B50="West",0.95,1)
A51: =Raw_Bookings!A52 | B51: =IF(TRIM(LOWER(Raw_Bookings!D52))="east","East",IF(TRIM(LOWER(Raw_Bookings!D52))="west","West",IF(TRIM(LOWER(Raw_Bookings!D52))="central","Central",IF(TRIM(LOWER(Raw_Bookings!D52))="south","South","UNKNOWN")))) | C51: =IFERROR(Raw_Bookings!H52*VLOOKUP(Raw_Bookings!I52,Rates!$A$2:$B$6,2,FALSE),Raw_Bookings!H52) | D51: =IF(Raw_Bookings!F52="New License","NEW",IF(OR(Raw_Bookings!F52="Renewal",Raw_Bookings!F52="Support"),"RECURRING","OTHER")) | E51: =IFERROR(VLOOKUP(Raw_Bookings!G52,Rep_Master!$A$2:$D$18,3,FALSE),"") | F51: =IFERROR(VLOOKUP(E51,Rep_Targets!$A$2:$D$9,4,FALSE),0) | G51: =IF(F51=0,"NO QUOTA FOUND",IF(C51>=F51*0.25,"On Track","Behind")) | H51: =C51*IF(B51="West",0.95,1)
A52: =Raw_Bookings!A53 | B52: =IF(TRIM(LOWER(Raw_Bookings!D53))="east","East",IF(TRIM(LOWER(Raw_Bookings!D53))="west","West",IF(TRIM(LOWER(Raw_Bookings!D53))="central","Central",IF(TRIM(LOWER(Raw_Bookings!D53))="south","South","UNKNOWN")))) | C52: =IFERROR(Raw_Bookings!H53*VLOOKUP(Raw_Bookings!I53,Rates!$A$2:$B$6,2,FALSE),Raw_Bookings!H53) | D52: =IF(Raw_Bookings!F53="New License","NEW",IF(OR(Raw_Bookings!F53="Renewal",Raw_Bookings!F53="Support"),"RECURRING","OTHER")) | E52: =IFERROR(VLOOKUP(Raw_Bookings!G53,Rep_Master!$A$2:$D$18,3,FALSE),"") | F52: =IFERROR(VLOOKUP(E52,Rep_Targets!$A$2:$D$9,4,FALSE),0) | G52: =IF(F52=0,"NO QUOTA FOUND",IF(C52>=F52*0.25,"On Track","Behind")) | H52: =C52*IF(B52="West",0.95,1)
A53: =Raw_Bookings!A54 | B53: =IF(TRIM(LOWER(Raw_Bookings!D54))="east","East",IF(TRIM(LOWER(Raw_Bookings!D54))="west","West",IF(TRIM(LOWER(Raw_Bookings!D54))="central","Central",IF(TRIM(LOWER(Raw_Bookings!D54))="south","South","UNKNOWN")))) | C53: =IFERROR(Raw_Bookings!H54*VLOOKUP(Raw_Bookings!I54,Rates!$A$2:$B$6,2,FALSE),Raw_Bookings!H54) | D53: =IF(Raw_Bookings!F54="New License","NEW",IF(OR(Raw_Bookings!F54="Renewal",Raw_Bookings!F54="Support"),"RECURRING","OTHER")) | E53: =IFERROR(VLOOKUP(Raw_Bookings!G54,Rep_Master!$A$2:$D$18,3,FALSE),"") | F53: =IFERROR(VLOOKUP(E53,Rep_Targets!$A$2:$D$9,4,FALSE),0) | G53: =IF(F53=0,"NO QUOTA FOUND",IF(C53>=F53*0.25,"On Track","Behind")) | H53: =C53*IF(B53="West",0.95,1)
A54: =Raw_Bookings!A55 | B54: =IF(TRIM(LOWER(Raw_Bookings!D55))="east","East",IF(TRIM(LOWER(Raw_Bookings!D55))="west","West",IF(TRIM(LOWER(Raw_Bookings!D55))="central","Central",IF(TRIM(LOWER(Raw_Bookings!D55))="south","South","UNKNOWN")))) | C54: =IFERROR(Raw_Bookings!H55*VLOOKUP(Raw_Bookings!I55,Rates!$A$2:$B$6,2,FALSE),Raw_Bookings!H55) | D54: =IF(Raw_Bookings!F55="New License","NEW",IF(OR(Raw_Bookings!F55="Renewal",Raw_Bookings!F55="Support"),"RECURRING","OTHER")) | E54: =IFERROR(VLOOKUP(Raw_Bookings!G55,Rep_Master!$A$2:$D$18,3,FALSE),"") | F54: =IFERROR(VLOOKUP(E54,Rep_Targets!$A$2:$D$9,4,FALSE),0) | G54: =IF(F54=0,"NO QUOTA FOUND",IF(C54>=F54*0.25,"On Track","Behind")) | H54: =C54*IF(B54="West",0.95,1)
A55: =Raw_Bookings!A56 | B55: =IF(TRIM(LOWER(Raw_Bookings!D56))="east","East",IF(TRIM(LOWER(Raw_Bookings!D56))="west","West",IF(TRIM(LOWER(Raw_Bookings!D56))="central","Central",IF(TRIM(LOWER(Raw_Bookings!D56))="south","South","UNKNOWN")))) | C55: =IFERROR(Raw_Bookings!H56*VLOOKUP(Raw_Bookings!I56,Rates!$A$2:$B$6,2,FALSE),Raw_Bookings!H56) | D55: =IF(Raw_Bookings!F56="New License","NEW",IF(OR(Raw_Bookings!F56="Renewal",Raw_Bookings!F56="Support"),"RECURRING","OTHER")) | E55: =IFERROR(VLOOKUP(Raw_Bookings!G56,Rep_Master!$A$2:$D$18,3,FALSE),"") | F55: =IFERROR(VLOOKUP(E55,Rep_Targets!$A$2:$D$9,4,FALSE),0) | G55: =IF(F55=0,"NO QUOTA FOUND",IF(C55>=F55*0.25,"On Track","Behind")) | H55: =C55*IF(B55="West",0.95,1)
A56: =Raw_Bookings!A57 | B56: =IF(TRIM(LOWER(Raw_Bookings!D57))="east","East",IF(TRIM(LOWER(Raw_Bookings!D57))="west","West",IF(TRIM(LOWER(Raw_Bookings!D57))="central","Central",IF(TRIM(LOWER(Raw_Bookings!D57))="south","South","UNKNOWN")))) | C56: =IFERROR(Raw_Bookings!H57*VLOOKUP(Raw_Bookings!I57,Rates!$A$2:$B$6,2,FALSE),Raw_Bookings!H57) | D56: =IF(Raw_Bookings!F57="New License","NEW",IF(OR(Raw_Bookings!F57="Renewal",Raw_Bookings!F57="Support"),"RECURRING","OTHER")) | E56: =IFERROR(VLOOKUP(Raw_Bookings!G57,Rep_Master!$A$2:$D$18,3,FALSE),"") | F56: =IFERROR(VLOOKUP(E56,Rep_Targets!$A$2:$D$9,4,FALSE),0) | G56: =IF(F56=0,"NO QUOTA FOUND",IF(C56>=F56*0.25,"On Track","Behind")) | H56: =C56*IF(B56="West",0.95,1)
... A146: =Raw_Bookings!A147 | B146: =IF(TRIM(LOWER(Raw_Bookings!D147))="east","East",IF(TRIM(LOWER(Raw_Bookings!D147))="west","West",IF(TRIM(LOWER(Raw_Bookings!D147))="central","Central",IF(TRIM(LOWER(Raw_Bookings!D147))="south","South","UNKNOWN")))) | C146: =IFERROR(Raw_Bookings!H147*VLOOKUP(Raw_Bookings!I147,Rates!$A$2:$B$6,2,FALSE),Raw_Bookings!H147) | D146: =IF(Raw_Bookings!F147="New License","NEW",IF(OR(Raw_Bookings!F147="Renewal",Raw_Bookings!F147="Support"),"RECURRING","OTHER")) | E146: =IFERROR(VLOOKUP(Raw_Bookings!G147,Rep_Master!$A$2:$D$18,3,FALSE),"") | F146: =IFERROR(VLOOKUP(E146,Rep_Targets!$A$2:$D$9,4,FALSE),0) | G146: =IF(F146=0,"NO QUOTA FOUND",IF(C146>=F146*0.25,"On Track","Behind")) | H146: =C146*IF(B146="West",0.95,1)
A147: =Raw_Bookings!A148 | B147: =IF(TRIM(LOWER(Raw_Bookings!D148))="east","East",IF(TRIM(LOWER(Raw_Bookings!D148))="west","West",IF(TRIM(LOWER(Raw_Bookings!D148))="central","Central",IF(TRIM(LOWER(Raw_Bookings!D148))="south","South","UNKNOWN")))) | C147: =IFERROR(Raw_Bookings!H148*VLOOKUP(Raw_Bookings!I148,Rates!$A$2:$B$6,2,FALSE),Raw_Bookings!H148) | D147: =IF(Raw_Bookings!F148="New License","NEW",IF(OR(Raw_Bookings!F148="Renewal",Raw_Bookings!F148="Support"),"RECURRING","OTHER")) | E147: =IFERROR(VLOOKUP(Raw_Bookings!G148,Rep_Master!$A$2:$D$18,3,FALSE),"") | F147: =IFERROR(VLOOKUP(E147,Rep_Targets!$A$2:$D$9,4,FALSE),0) | G147: =IF(F147=0,"NO QUOTA FOUND",IF(C147>=F147*0.25,"On Track","Behind")) | H147: 5464.9 | I147: ADJ146 | J147: mgr adj - see email 3/12
A148: =Raw_Bookings!A149 | B148: =IF(TRIM(LOWER(Raw_Bookings!D149))="east","East",IF(TRIM(LOWER(Raw_Bookings!D149))="west","West",IF(TRIM(LOWER(Raw_Bookings!D149))="central","Central",IF(TRIM(LOWER(Raw_Bookings!D149))="south","South","UNKNOWN")))) | C148: =IFERROR(Raw_Bookings!H149*VLOOKUP(Raw_Bookings!I149,Rates!$A$2:$B$6,2,FALSE),Raw_Bookings!H149) | D148: =IF(Raw_Bookings!F149="New License","NEW",IF(OR(Raw_Bookings!F149="Renewal",Raw_Bookings!F149="Support"),"RECURRING","OTHER")) | E148: =IFERROR(VLOOKUP(Raw_Bookings!G149,Rep_Master!$A$2:$D$18,3,FALSE),"") | F148: =IFERROR(VLOOKUP(E148,Rep_Targets!$A$2:$D$9,4,FALSE),0) | G148: =IF(F148=0,"NO QUOTA FOUND",IF(C148>=F148*0.25,"On Track","Behind")) | H148: =C148*IF(B148="West",0.95,1)
A149: =Raw_Bookings!A150 | B149: =IF(TRIM(LOWER(Raw_Bookings!D150))="east","East",IF(TRIM(LOWER(Raw_Bookings!D150))="west","West",IF(TRIM(LOWER(Raw_Bookings!D150))="central","Central",IF(TRIM(LOWER(Raw_Bookings!D150))="south","South","UNKNOWN")))) | C149: =IFERROR(Raw_Bookings!H150*VLOOKUP(Raw_Bookings!I150,Rates!$A$2:$B$6,2,FALSE),Raw_Bookings!H150) | D149: =IF(Raw_Bookings!F150="New License","NEW",IF(OR(Raw_Bookings!F150="Renewal",Raw_Bookings!F150="Support"),"RECURRING","OTHER")) | E149: =IFERROR(VLOOKUP(Raw_Bookings!G150,Rep_Master!$A$2:$D$18,3,FALSE),"") | F149: =IFERROR(VLOOKUP(E149,Rep_Targets!$A$2:$D$9,4,FALSE),0) | G149: =IF(F149=0,"NO QUOTA FOUND",IF(C149>=F149*0.25,"On Track","Behind")) | H149: =C149*IF(B149="West",0.95,1)
A150: =Raw_Bookings!A151 | B150: =IF(TRIM(LOWER(Raw_Bookings!D151))="east","East",IF(TRIM(LOWER(Raw_Bookings!D151))="west","West",IF(TRIM(LOWER(Raw_Bookings!D151))="central","Central",IF(TRIM(LOWER(Raw_Bookings!D151))="south","South","UNKNOWN")))) | C150: =IFERROR(Raw_Bookings!H151*VLOOKUP(Raw_Bookings!I151,Rates!$A$2:$B$6,2,FALSE),Raw_Bookings!H151) | D150: =IF(Raw_Bookings!F151="New License","NEW",IF(OR(Raw_Bookings!F151="Renewal",Raw_Bookings!F151="Support"),"RECURRING","OTHER")) | E150: =IFERROR(VLOOKUP(Raw_Bookings!G151,Rep_Master!$A$2:$D$18,3,FALSE),"") | F150: =IFERROR(VLOOKUP(E150,Rep_Targets!$A$2:$D$9,4,FALSE),0) | G150: =IF(F150=0,"NO QUOTA FOUND",IF(C150>=F150*0.25,"On Track","Behind")) | H150: =C150*IF(B150="West",0.95,1)
A151: =Raw_Bookings!A152 | B151: =IF(TRIM(LOWER(Raw_Bookings!D152))="east","East",IF(TRIM(LOWER(Raw_Bookings!D152))="west","West",IF(TRIM(LOWER(Raw_Bookings!D152))="central","Central",IF(TRIM(LOWER(Raw_Bookings!D152))="south","South","UNKNOWN")))) | C151: =IFERROR(Raw_Bookings!H152*VLOOKUP(Raw_Bookings!I152,Rates!$A$2:$B$6,2,FALSE),Raw_Bookings!H152) | D151: =IF(Raw_Bookings!F152="New License","NEW",IF(OR(Raw_Bookings!F152="Renewal",Raw_Bookings!F152="Support"),"RECURRING","OTHER")) | E151: =IFERROR(VLOOKUP(Raw_Bookings!G152,Rep_Master!$A$2:$D$18,3,FALSE),"") | F151: =IFERROR(VLOOKUP(E151,Rep_Targets!$A$2:$D$9,4,FALSE),0) | G151: =IF(F151=0,"NO QUOTA FOUND",IF(C151>=F151*0.25,"On Track","Behind")) | H151: =C151*IF(B151="West",0.95,1)
A152: =Raw_Bookings!A153 | B152: =IF(TRIM(LOWER(Raw_Bookings!D153))="east","East",IF(TRIM(LOWER(Raw_Bookings!D153))="west","West",IF(TRIM(LOWER(Raw_Bookings!D153))="central","Central",IF(TRIM(LOWER(Raw_Bookings!D153))="south","South","UNKNOWN")))) | C152: =IFERROR(Raw_Bookings!H153*VLOOKUP(Raw_Bookings!I153,Rates!$A$2:$B$6,2,FALSE),Raw_Bookings!H153) | D152: =IF(Raw_Bookings!F153="New License","NEW",IF(OR(Raw_Bookings!F153="Renewal",Raw_Bookings!F153="Support"),"RECURRING","OTHER")) | E152: =IFERROR(VLOOKUP(Raw_Bookings!G153,Rep_Master!$A$2:$D$18,3,FALSE),"") | F152: =IFERROR(VLOOKUP(E152,Rep_Targets!$A$2:$D$9,4,FALSE),0) | G152: =IF(F152=0,"NO QUOTA FOUND",IF(C152>=F152*0.25,"On Track","Behind")) | H152: =C152*IF(B152="West",0.95,1)
A153: =Raw_Bookings!A154 | B153: =IF(TRIM(LOWER(Raw_Bookings!D154))="east","East",IF(TRIM(LOWER(Raw_Bookings!D154))="west","West",IF(TRIM(LOWER(Raw_Bookings!D154))="central","Central",IF(TRIM(LOWER(Raw_Bookings!D154))="south","South","UNKNOWN")))) | C153: =IFERROR(Raw_Bookings!H154*VLOOKUP(Raw_Bookings!I154,Rates!$A$2:$B$6,2,FALSE),Raw_Bookings!H154) | D153: =IF(Raw_Bookings!F154="New License","NEW",IF(OR(Raw_Bookings!F154="Renewal",Raw_Bookings!F154="Support"),"RECURRING","OTHER")) | E153: =IFERROR(VLOOKUP(Raw_Bookings!G154,Rep_Master!$A$2:$D$18,3,FALSE),"") | F153: =IFERROR(VLOOKUP(E153,Rep_Targets!$A$2:$D$9,4,FALSE),0) | G153: =IF(F153=0,"NO QUOTA FOUND",IF(C153>=F153*0.25,"On Track","Behind")) | H153: =C153*IF(B153="West",0.95,1)
A154: =Raw_Bookings!A155 | B154: =IF(TRIM(LOWER(Raw_Bookings!D155))="east","East",IF(TRIM(LOWER(Raw_Bookings!D155))="west","West",IF(TRIM(LOWER(Raw_Bookings!D155))="central","Central",IF(TRIM(LOWER(Raw_Bookings!D155))="south","South","UNKNOWN")))) | C154: =IFERROR(Raw_Bookings!H155*VLOOKUP(Raw_Bookings!I155,Rates!$A$2:$B$6,2,FALSE),Raw_Bookings!H155) | D154: =IF(Raw_Bookings!F155="New License","NEW",IF(OR(Raw_Bookings!F155="Renewal",Raw_Bookings!F155="Support"),"RECURRING","OTHER")) | E154: =IFERROR(VLOOKUP(Raw_Bookings!G155,Rep_Master!$A$2:$D$18,3,FALSE),"") | F154: =IFERROR(VLOOKUP(E154,Rep_Targets!$A$2:$D$9,4,FALSE),0) | G154: =IF(F154=0,"NO QUOTA FOUND",IF(C154>=F154*0.25,"On Track","Behind")) | H154: =C154*IF(B154="West",0.95,1)
A155: =Raw_Bookings!A156 | B155: =IF(TRIM(LOWER(Raw_Bookings!D156))="east","East",IF(TRIM(LOWER(Raw_Bookings!D156))="west","West",IF(TRIM(LOWER(Raw_Bookings!D156))="central","Central",IF(TRIM(LOWER(Raw_Bookings!D156))="south","South","UNKNOWN")))) | C155: =IFERROR(Raw_Bookings!H156*VLOOKUP(Raw_Bookings!I156,Rates!$A$2:$B$6,2,FALSE),Raw_Bookings!H156) | D155: =IF(Raw_Bookings!F156="New License","NEW",IF(OR(Raw_Bookings!F156="Renewal",Raw_Bookings!F156="Support"),"RECURRING","OTHER")) | E155: =IFERROR(VLOOKUP(Raw_Bookings!G156,Rep_Master!$A$2:$D$18,3,FALSE),"") | F155: =IFERROR(VLOOKUP(E155,Rep_Targets!$A$2:$D$9,4,FALSE),0) | G155: =IF(F155=0,"NO QUOTA FOUND",IF(C155>=F155*0.25,"On Track","Behind")) | H155: =C155*IF(B155="West",0.95,1)
A156: =Raw_Bookings!A157 | B156: =IF(TRIM(LOWER(Raw_Bookings!D157))="east","East",IF(TRIM(LOWER(Raw_Bookings!D157))="west","West",IF(TRIM(LOWER(Raw_Bookings!D157))="central","Central",IF(TRIM(LOWER(Raw_Bookings!D157))="south","South","UNKNOWN")))) | C156: =IFERROR(Raw_Bookings!H157*VLOOKUP(Raw_Bookings!I157,Rates!$A$2:$B$6,2,FALSE),Raw_Bookings!H157) | D156: =IF(Raw_Bookings!F157="New License","NEW",IF(OR(Raw_Bookings!F157="Renewal",Raw_Bookings!F157="Support"),"RECURRING","OTHER")) | E156: =IFERROR(VLOOKUP(Raw_Bookings!G157,Rep_Master!$A$2:$D$18,3,FALSE),"") | F156: =IFERROR(VLOOKUP(E156,Rep_Targets!$A$2:$D$9,4,FALSE),0) | G156: =IF(F156=0,"NO QUOTA FOUND",IF(C156>=F156*0.25,"On Track","Behind")) | H156: =C156*IF(B156="West",0.95,1)
A157: =Raw_Bookings!A158 | B157: =IF(TRIM(LOWER(Raw_Bookings!D158))="east","East",IF(TRIM(LOWER(Raw_Bookings!D158))="west","West",IF(TRIM(LOWER(Raw_Bookings!D158))="central","Central",IF(TRIM(LOWER(Raw_Bookings!D158))="south","South","UNKNOWN")))) | C157: =IFERROR(Raw_Bookings!H158*VLOOKUP(Raw_Bookings!I158,Rates!$A$2:$B$6,2,FALSE),Raw_Bookings!H158) | D157: =IF(Raw_Bookings!F158="New License","NEW",IF(OR(Raw_Bookings!F158="Renewal",Raw_Bookings!F158="Support"),"RECURRING","OTHER")) | E157: =IFERROR(VLOOKUP(Raw_Bookings!G158,Rep_Master!$A$2:$D$18,3,FALSE),"") | F157: =IFERROR(VLOOKUP(E157,Rep_Targets!$A$2:$D$9,4,FALSE),0) | G157: =IF(F157=0,"NO QUOTA FOUND",IF(C157>=F157*0.25,"On Track","Behind")) | H157: =C157*IF(B157="West",0.95,1)
A158: =Raw_Bookings!A159 | B158: =IF(TRIM(LOWER(Raw_Bookings!D159))="east","East",IF(TRIM(LOWER(Raw_Bookings!D159))="west","West",IF(TRIM(LOWER(Raw_Bookings!D159))="central","Central",IF(TRIM(LOWER(Raw_Bookings!D159))="south","South","UNKNOWN")))) | C158: =IFERROR(Raw_Bookings!H159*VLOOKUP(Raw_Bookings!I159,Rates!$A$2:$B$6,2,FALSE),Raw_Bookings!H159) | D158: =IF(Raw_Bookings!F159="New License","NEW",IF(OR(Raw_Bookings!F159="Renewal",Raw_Bookings!F159="Support"),"RECURRING","OTHER")) | E158: =IFERROR(VLOOKUP(Raw_Bookings!G159,Rep_Master!$A$2:$D$18,3,FALSE),"") | F158: =IFERROR(VLOOKUP(E158,Rep_Targets!$A$2:$D$9,4,FALSE),0) | G158: =IF(F158=0,"NO QUOTA FOUND",IF(C158>=F158*0.25,"On Track","Behind")) | H158: =C158*IF(B158="West",0.95,1)
...

Sheet Regional_Summary
A1: REGIONAL BOOKINGS SUMMARY - FINAL - v7
A3: Region | B3: NEW | C3: RECURRING | D3: OTHER | E3: Total | F3: % of Grand Total
A4: East | B4: =SUMIFS(Calc!$H$2:$H404,Calc!$B$2:$B404,$A4,Calc!$D$2:$D404,B$3) | C4: =SUMIFS(Calc!$H$2:$H404,Calc!$B$2:$B404,$A4,Calc!$D$2:$D404,C$3) | D4: =SUMIFS(Calc!$H$2:$H404,Calc!$B$2:$B404,$A4,Calc!$D$2:$D404,D$3) | E4: =SUM(B4:D4) | F4: =IF($E$9=0,0,E4/$E$9)
A5: West | B5: =SUMIFS(Calc!$H$2:$H404,Calc!$B$2:$B404,$A5,Calc!$D$2:$D404,B$3) | C5: =SUMIFS(Calc!$H$2:$H404,Calc!$B$2:$B404,$A5,Calc!$D$2:$D404,C$3) | D5: =SUMIFS(Calc!$H$2:$H404,Calc!$B$2:$B404,$A5,Calc!$D$2:$D404,D$3) | E5: =SUM(B5:D5) | F5: =IF($E$9=0,0,E5/$E$9)
A6: Central | B6: =SUMIFS(Calc!$H$2:$H404,Calc!$B$2:$B404,$A6,Calc!$D$2:$D404,B$3) | C6: =SUMIFS(Calc!$H$2:$H404,Calc!$B$2:$B404,$A6,Calc!$D$2:$D404,C$3) | D6: =SUMIFS(Calc!$H$2:$H404,Calc!$B$2:$B404,$A6,Calc!$D$2:$D404,D$3) | E6: =SUM(B6:D6) | F6: =IF($E$9=0,0,E6/$E$9)
A7: South | B7: =SUMIFS(Calc!$H$2:$H404,Calc!$B$2:$B404,$A7,Calc!$D$2:$D404,B$3) | C7: =SUMIFS(Calc!$H$2:$H404,Calc!$B$2:$B404,$A7,Calc!$D$2:$D404,C$3) | D7: =SUMIFS(Calc!$H$2:$H404,Calc!$B$2:$B404,$A7,Calc!$D$2:$D404,D$3) | E7: =SUM(B7:D7) | F7: =IF($E$9=0,0,E7/$E$9)
A9: GRAND TOTAL | E9: =SUM(E4:E7)+5000 | G9: true-up per Finance (Jan) - DO NOT REMOVE
